[2025-02-25 01:32:54 -0800] [2636589] [INFO] Starting gunicorn 23.0.0
[2025-02-25 01:32:54 -0800] [2636589] [INFO] Listening at: http://0.0.0.0:65216 (2636589)
[2025-02-25 01:32:54 -0800] [2636589] [INFO] Using worker: sync
[2025-02-25 01:32:54 -0800] [2636596] [INFO] Booting worker with pid: 2636596
[2025-02-25 01:33:17,526] ERROR in app: Exception on / [GET]
Traceback (most recent call last):
  File "/nfs/stak/users/kimh22/public_html/cs340_group39/NutriSphere_admin_panel/venv/lib64/python3.9/site-packages/flask/app.py", line 1511, in wsgi_app
    response = self.full_dispatch_request()
  File "/nfs/stak/users/kimh22/public_html/cs340_group39/NutriSphere_admin_panel/venv/lib64/python3.9/site-packages/flask/app.py", line 919, in full_dispatch_request
    rv = self.handle_user_exception(e)
  File "/nfs/stak/users/kimh22/public_html/cs340_group39/NutriSphere_admin_panel/venv/lib64/python3.9/site-packages/flask/app.py", line 917, in full_dispatch_request
    rv = self.dispatch_request()
  File "/nfs/stak/users/kimh22/public_html/cs340_group39/NutriSphere_admin_panel/venv/lib64/python3.9/site-packages/flask/app.py", line 902, in dispatch_request
    return self.ensure_sync(self.view_functions[rule.endpoint])(**view_args)  # type: ignore[no-any-return]
  File "/nfs/stak/users/kimh22/public_html/cs340_group39/NutriSphere_admin_panel/app.py", line 18, in home
    return render_template("index.html")
  File "/nfs/stak/users/kimh22/public_html/cs340_group39/NutriSphere_admin_panel/venv/lib64/python3.9/site-packages/flask/templating.py", line 150, in render_template
    return _render(app, template, context)
  File "/nfs/stak/users/kimh22/public_html/cs340_group39/NutriSphere_admin_panel/venv/lib64/python3.9/site-packages/flask/templating.py", line 131, in _render
    rv = template.render(context)
  File "/nfs/stak/users/kimh22/public_html/cs340_group39/NutriSphere_admin_panel/venv/lib64/python3.9/site-packages/jinja2/environment.py", line 1295, in render
    self.environment.handle_exception()
  File "/nfs/stak/users/kimh22/public_html/cs340_group39/NutriSphere_admin_panel/venv/lib64/python3.9/site-packages/jinja2/environment.py", line 942, in handle_exception
    raise rewrite_traceback_stack(source=source)
  File "/nfs/stak/users/kimh22/public_html/cs340_group39/NutriSphere_admin_panel/templates/index.html", line 16, in top-level template code
    <a href="{{ url_for('daily-trackers') }}">üóìÔ∏è Daily Trackers</a>
  File "/nfs/stak/users/kimh22/public_html/cs340_group39/NutriSphere_admin_panel/venv/lib64/python3.9/site-packages/flask/app.py", line 1121, in url_for
    return self.handle_url_build_error(error, endpoint, values)
  File "/nfs/stak/users/kimh22/public_html/cs340_group39/NutriSphere_admin_panel/venv/lib64/python3.9/site-packages/flask/app.py", line 1110, in url_for
    rv = url_adapter.build(  # type: ignore[union-attr]
  File "/nfs/stak/users/kimh22/public_html/cs340_group39/NutriSphere_admin_panel/venv/lib64/python3.9/site-packages/werkzeug/routing/map.py", line 924, in build
    raise BuildError(endpoint, values, method, self)
werkzeug.routing.exceptions.BuildError: Could not build url for endpoint 'daily-trackers'. Did you mean 'update_user' instead?
[2025-02-25 01:33:18,969] ERROR in app: Exception on / [GET]
Traceback (most recent call last):
  File "/nfs/stak/users/kimh22/public_html/cs340_group39/NutriSphere_admin_panel/venv/lib64/python3.9/site-packages/flask/app.py", line 1511, in wsgi_app
    response = self.full_dispatch_request()
  File "/nfs/stak/users/kimh22/public_html/cs340_group39/NutriSphere_admin_panel/venv/lib64/python3.9/site-packages/flask/app.py", line 919, in full_dispatch_request
    rv = self.handle_user_exception(e)
  File "/nfs/stak/users/kimh22/public_html/cs340_group39/NutriSphere_admin_panel/venv/lib64/python3.9/site-packages/flask/app.py", line 917, in full_dispatch_request
    rv = self.dispatch_request()
  File "/nfs/stak/users/kimh22/public_html/cs340_group39/NutriSphere_admin_panel/venv/lib64/python3.9/site-packages/flask/app.py", line 902, in dispatch_request
    return self.ensure_sync(self.view_functions[rule.endpoint])(**view_args)  # type: ignore[no-any-return]
  File "/nfs/stak/users/kimh22/public_html/cs340_group39/NutriSphere_admin_panel/app.py", line 18, in home
    return render_template("index.html")
  File "/nfs/stak/users/kimh22/public_html/cs340_group39/NutriSphere_admin_panel/venv/lib64/python3.9/site-packages/flask/templating.py", line 150, in render_template
    return _render(app, template, context)
  File "/nfs/stak/users/kimh22/public_html/cs340_group39/NutriSphere_admin_panel/venv/lib64/python3.9/site-packages/flask/templating.py", line 131, in _render
    rv = template.render(context)
  File "/nfs/stak/users/kimh22/public_html/cs340_group39/NutriSphere_admin_panel/venv/lib64/python3.9/site-packages/jinja2/environment.py", line 1295, in render
    self.environment.handle_exception()
  File "/nfs/stak/users/kimh22/public_html/cs340_group39/NutriSphere_admin_panel/venv/lib64/python3.9/site-packages/jinja2/environment.py", line 942, in handle_exception
    raise rewrite_traceback_stack(source=source)
  File "/nfs/stak/users/kimh22/public_html/cs340_group39/NutriSphere_admin_panel/templates/index.html", line 16, in top-level template code
    <a href="{{ url_for('daily-trackers') }}">üóìÔ∏è Daily Trackers</a>
  File "/nfs/stak/users/kimh22/public_html/cs340_group39/NutriSphere_admin_panel/venv/lib64/python3.9/site-packages/flask/app.py", line 1121, in url_for
    return self.handle_url_build_error(error, endpoint, values)
  File "/nfs/stak/users/kimh22/public_html/cs340_group39/NutriSphere_admin_panel/venv/lib64/python3.9/site-packages/flask/app.py", line 1110, in url_for
    rv = url_adapter.build(  # type: ignore[union-attr]
  File "/nfs/stak/users/kimh22/public_html/cs340_group39/NutriSphere_admin_panel/venv/lib64/python3.9/site-packages/werkzeug/routing/map.py", line 924, in build
    raise BuildError(endpoint, values, method, self)
werkzeug.routing.exceptions.BuildError: Could not build url for endpoint 'daily-trackers'. Did you mean 'update_user' instead?
[2025-02-25 01:33:19,129] ERROR in app: Exception on / [GET]
Traceback (most recent call last):
  File "/nfs/stak/users/kimh22/public_html/cs340_group39/NutriSphere_admin_panel/venv/lib64/python3.9/site-packages/flask/app.py", line 1511, in wsgi_app
    response = self.full_dispatch_request()
  File "/nfs/stak/users/kimh22/public_html/cs340_group39/NutriSphere_admin_panel/venv/lib64/python3.9/site-packages/flask/app.py", line 919, in full_dispatch_request
    rv = self.handle_user_exception(e)
  File "/nfs/stak/users/kimh22/public_html/cs340_group39/NutriSphere_admin_panel/venv/lib64/python3.9/site-packages/flask/app.py", line 917, in full_dispatch_request
    rv = self.dispatch_request()
  File "/nfs/stak/users/kimh22/public_html/cs340_group39/NutriSphere_admin_panel/venv/lib64/python3.9/site-packages/flask/app.py", line 902, in dispatch_request
    return self.ensure_sync(self.view_functions[rule.endpoint])(**view_args)  # type: ignore[no-any-return]
  File "/nfs/stak/users/kimh22/public_html/cs340_group39/NutriSphere_admin_panel/app.py", line 18, in home
    return render_template("index.html")
  File "/nfs/stak/users/kimh22/public_html/cs340_group39/NutriSphere_admin_panel/venv/lib64/python3.9/site-packages/flask/templating.py", line 150, in render_template
    return _render(app, template, context)
  File "/nfs/stak/users/kimh22/public_html/cs340_group39/NutriSphere_admin_panel/venv/lib64/python3.9/site-packages/flask/templating.py", line 131, in _render
    rv = template.render(context)
  File "/nfs/stak/users/kimh22/public_html/cs340_group39/NutriSphere_admin_panel/venv/lib64/python3.9/site-packages/jinja2/environment.py", line 1295, in render
    self.environment.handle_exception()
  File "/nfs/stak/users/kimh22/public_html/cs340_group39/NutriSphere_admin_panel/venv/lib64/python3.9/site-packages/jinja2/environment.py", line 942, in handle_exception
    raise rewrite_traceback_stack(source=source)
  File "/nfs/stak/users/kimh22/public_html/cs340_group39/NutriSphere_admin_panel/templates/index.html", line 16, in top-level template code
    <a href="{{ url_for('daily-trackers') }}">üóìÔ∏è Daily Trackers</a>
  File "/nfs/stak/users/kimh22/public_html/cs340_group39/NutriSphere_admin_panel/venv/lib64/python3.9/site-packages/flask/app.py", line 1121, in url_for
    return self.handle_url_build_error(error, endpoint, values)
  File "/nfs/stak/users/kimh22/public_html/cs340_group39/NutriSphere_admin_panel/venv/lib64/python3.9/site-packages/flask/app.py", line 1110, in url_for
    rv = url_adapter.build(  # type: ignore[union-attr]
  File "/nfs/stak/users/kimh22/public_html/cs340_group39/NutriSphere_admin_panel/venv/lib64/python3.9/site-packages/werkzeug/routing/map.py", line 924, in build
    raise BuildError(endpoint, values, method, self)
werkzeug.routing.exceptions.BuildError: Could not build url for endpoint 'daily-trackers'. Did you mean 'update_user' instead?
[2025-02-25 01:33:19,273] ERROR in app: Exception on / [GET]
Traceback (most recent call last):
  File "/nfs/stak/users/kimh22/public_html/cs340_group39/NutriSphere_admin_panel/venv/lib64/python3.9/site-packages/flask/app.py", line 1511, in wsgi_app
    response = self.full_dispatch_request()
  File "/nfs/stak/users/kimh22/public_html/cs340_group39/NutriSphere_admin_panel/venv/lib64/python3.9/site-packages/flask/app.py", line 919, in full_dispatch_request
    rv = self.handle_user_exception(e)
  File "/nfs/stak/users/kimh22/public_html/cs340_group39/NutriSphere_admin_panel/venv/lib64/python3.9/site-packages/flask/app.py", line 917, in full_dispatch_request
    rv = self.dispatch_request()
  File "/nfs/stak/users/kimh22/public_html/cs340_group39/NutriSphere_admin_panel/venv/lib64/python3.9/site-packages/flask/app.py", line 902, in dispatch_request
    return self.ensure_sync(self.view_functions[rule.endpoint])(**view_args)  # type: ignore[no-any-return]
  File "/nfs/stak/users/kimh22/public_html/cs340_group39/NutriSphere_admin_panel/app.py", line 18, in home
    return render_template("index.html")
  File "/nfs/stak/users/kimh22/public_html/cs340_group39/NutriSphere_admin_panel/venv/lib64/python3.9/site-packages/flask/templating.py", line 150, in render_template
    return _render(app, template, context)
  File "/nfs/stak/users/kimh22/public_html/cs340_group39/NutriSphere_admin_panel/venv/lib64/python3.9/site-packages/flask/templating.py", line 131, in _render
    rv = template.render(context)
  File "/nfs/stak/users/kimh22/public_html/cs340_group39/NutriSphere_admin_panel/venv/lib64/python3.9/site-packages/jinja2/environment.py", line 1295, in render
    self.environment.handle_exception()
  File "/nfs/stak/users/kimh22/public_html/cs340_group39/NutriSphere_admin_panel/venv/lib64/python3.9/site-packages/jinja2/environment.py", line 942, in handle_exception
    raise rewrite_traceback_stack(source=source)
  File "/nfs/stak/users/kimh22/public_html/cs340_group39/NutriSphere_admin_panel/templates/index.html", line 16, in top-level template code
    <a href="{{ url_for('daily-trackers') }}">üóìÔ∏è Daily Trackers</a>
  File "/nfs/stak/users/kimh22/public_html/cs340_group39/NutriSphere_admin_panel/venv/lib64/python3.9/site-packages/flask/app.py", line 1121, in url_for
    return self.handle_url_build_error(error, endpoint, values)
  File "/nfs/stak/users/kimh22/public_html/cs340_group39/NutriSphere_admin_panel/venv/lib64/python3.9/site-packages/flask/app.py", line 1110, in url_for
    rv = url_adapter.build(  # type: ignore[union-attr]
  File "/nfs/stak/users/kimh22/public_html/cs340_group39/NutriSphere_admin_panel/venv/lib64/python3.9/site-packages/werkzeug/routing/map.py", line 924, in build
    raise BuildError(endpoint, values, method, self)
werkzeug.routing.exceptions.BuildError: Could not build url for endpoint 'daily-trackers'. Did you mean 'update_user' instead?
[2025-02-25 01:33:19,414] ERROR in app: Exception on / [GET]
Traceback (most recent call last):
  File "/nfs/stak/users/kimh22/public_html/cs340_group39/NutriSphere_admin_panel/venv/lib64/python3.9/site-packages/flask/app.py", line 1511, in wsgi_app
    response = self.full_dispatch_request()
  File "/nfs/stak/users/kimh22/public_html/cs340_group39/NutriSphere_admin_panel/venv/lib64/python3.9/site-packages/flask/app.py", line 919, in full_dispatch_request
    rv = self.handle_user_exception(e)
  File "/nfs/stak/users/kimh22/public_html/cs340_group39/NutriSphere_admin_panel/venv/lib64/python3.9/site-packages/flask/app.py", line 917, in full_dispatch_request
    rv = self.dispatch_request()
  File "/nfs/stak/users/kimh22/public_html/cs340_group39/NutriSphere_admin_panel/venv/lib64/python3.9/site-packages/flask/app.py", line 902, in dispatch_request
    return self.ensure_sync(self.view_functions[rule.endpoint])(**view_args)  # type: ignore[no-any-return]
  File "/nfs/stak/users/kimh22/public_html/cs340_group39/NutriSphere_admin_panel/app.py", line 18, in home
    return render_template("index.html")
  File "/nfs/stak/users/kimh22/public_html/cs340_group39/NutriSphere_admin_panel/venv/lib64/python3.9/site-packages/flask/templating.py", line 150, in render_template
    return _render(app, template, context)
  File "/nfs/stak/users/kimh22/public_html/cs340_group39/NutriSphere_admin_panel/venv/lib64/python3.9/site-packages/flask/templating.py", line 131, in _render
    rv = template.render(context)
  File "/nfs/stak/users/kimh22/public_html/cs340_group39/NutriSphere_admin_panel/venv/lib64/python3.9/site-packages/jinja2/environment.py", line 1295, in render
    self.environment.handle_exception()
  File "/nfs/stak/users/kimh22/public_html/cs340_group39/NutriSphere_admin_panel/venv/lib64/python3.9/site-packages/jinja2/environment.py", line 942, in handle_exception
    raise rewrite_traceback_stack(source=source)
  File "/nfs/stak/users/kimh22/public_html/cs340_group39/NutriSphere_admin_panel/templates/index.html", line 16, in top-level template code
    <a href="{{ url_for('daily-trackers') }}">üóìÔ∏è Daily Trackers</a>
  File "/nfs/stak/users/kimh22/public_html/cs340_group39/NutriSphere_admin_panel/venv/lib64/python3.9/site-packages/flask/app.py", line 1121, in url_for
    return self.handle_url_build_error(error, endpoint, values)
  File "/nfs/stak/users/kimh22/public_html/cs340_group39/NutriSphere_admin_panel/venv/lib64/python3.9/site-packages/flask/app.py", line 1110, in url_for
    rv = url_adapter.build(  # type: ignore[union-attr]
  File "/nfs/stak/users/kimh22/public_html/cs340_group39/NutriSphere_admin_panel/venv/lib64/python3.9/site-packages/werkzeug/routing/map.py", line 924, in build
    raise BuildError(endpoint, values, method, self)
werkzeug.routing.exceptions.BuildError: Could not build url for endpoint 'daily-trackers'. Did you mean 'update_user' instead?
[2025-02-25 01:33:19,553] ERROR in app: Exception on / [GET]
Traceback (most recent call last):
  File "/nfs/stak/users/kimh22/public_html/cs340_group39/NutriSphere_admin_panel/venv/lib64/python3.9/site-packages/flask/app.py", line 1511, in wsgi_app
    response = self.full_dispatch_request()
  File "/nfs/stak/users/kimh22/public_html/cs340_group39/NutriSphere_admin_panel/venv/lib64/python3.9/site-packages/flask/app.py", line 919, in full_dispatch_request
    rv = self.handle_user_exception(e)
  File "/nfs/stak/users/kimh22/public_html/cs340_group39/NutriSphere_admin_panel/venv/lib64/python3.9/site-packages/flask/app.py", line 917, in full_dispatch_request
    rv = self.dispatch_request()
  File "/nfs/stak/users/kimh22/public_html/cs340_group39/NutriSphere_admin_panel/venv/lib64/python3.9/site-packages/flask/app.py", line 902, in dispatch_request
    return self.ensure_sync(self.view_functions[rule.endpoint])(**view_args)  # type: ignore[no-any-return]
  File "/nfs/stak/users/kimh22/public_html/cs340_group39/NutriSphere_admin_panel/app.py", line 18, in home
    return render_template("index.html")
  File "/nfs/stak/users/kimh22/public_html/cs340_group39/NutriSphere_admin_panel/venv/lib64/python3.9/site-packages/flask/templating.py", line 150, in render_template
    return _render(app, template, context)
  File "/nfs/stak/users/kimh22/public_html/cs340_group39/NutriSphere_admin_panel/venv/lib64/python3.9/site-packages/flask/templating.py", line 131, in _render
    rv = template.render(context)
  File "/nfs/stak/users/kimh22/public_html/cs340_group39/NutriSphere_admin_panel/venv/lib64/python3.9/site-packages/jinja2/environment.py", line 1295, in render
    self.environment.handle_exception()
  File "/nfs/stak/users/kimh22/public_html/cs340_group39/NutriSphere_admin_panel/venv/lib64/python3.9/site-packages/jinja2/environment.py", line 942, in handle_exception
    raise rewrite_traceback_stack(source=source)
  File "/nfs/stak/users/kimh22/public_html/cs340_group39/NutriSphere_admin_panel/templates/index.html", line 16, in top-level template code
    <a href="{{ url_for('daily-trackers') }}">üóìÔ∏è Daily Trackers</a>
  File "/nfs/stak/users/kimh22/public_html/cs340_group39/NutriSphere_admin_panel/venv/lib64/python3.9/site-packages/flask/app.py", line 1121, in url_for
    return self.handle_url_build_error(error, endpoint, values)
  File "/nfs/stak/users/kimh22/public_html/cs340_group39/NutriSphere_admin_panel/venv/lib64/python3.9/site-packages/flask/app.py", line 1110, in url_for
    rv = url_adapter.build(  # type: ignore[union-attr]
  File "/nfs/stak/users/kimh22/public_html/cs340_group39/NutriSphere_admin_panel/venv/lib64/python3.9/site-packages/werkzeug/routing/map.py", line 924, in build
    raise BuildError(endpoint, values, method, self)
werkzeug.routing.exceptions.BuildError: Could not build url for endpoint 'daily-trackers'. Did you mean 'update_user' instead?
[2025-02-25 01:33:19,706] ERROR in app: Exception on / [GET]
Traceback (most recent call last):
  File "/nfs/stak/users/kimh22/public_html/cs340_group39/NutriSphere_admin_panel/venv/lib64/python3.9/site-packages/flask/app.py", line 1511, in wsgi_app
    response = self.full_dispatch_request()
  File "/nfs/stak/users/kimh22/public_html/cs340_group39/NutriSphere_admin_panel/venv/lib64/python3.9/site-packages/flask/app.py", line 919, in full_dispatch_request
    rv = self.handle_user_exception(e)
  File "/nfs/stak/users/kimh22/public_html/cs340_group39/NutriSphere_admin_panel/venv/lib64/python3.9/site-packages/flask/app.py", line 917, in full_dispatch_request
    rv = self.dispatch_request()
  File "/nfs/stak/users/kimh22/public_html/cs340_group39/NutriSphere_admin_panel/venv/lib64/python3.9/site-packages/flask/app.py", line 902, in dispatch_request
    return self.ensure_sync(self.view_functions[rule.endpoint])(**view_args)  # type: ignore[no-any-return]
  File "/nfs/stak/users/kimh22/public_html/cs340_group39/NutriSphere_admin_panel/app.py", line 18, in home
    return render_template("index.html")
  File "/nfs/stak/users/kimh22/public_html/cs340_group39/NutriSphere_admin_panel/venv/lib64/python3.9/site-packages/flask/templating.py", line 150, in render_template
    return _render(app, template, context)
  File "/nfs/stak/users/kimh22/public_html/cs340_group39/NutriSphere_admin_panel/venv/lib64/python3.9/site-packages/flask/templating.py", line 131, in _render
    rv = template.render(context)
  File "/nfs/stak/users/kimh22/public_html/cs340_group39/NutriSphere_admin_panel/venv/lib64/python3.9/site-packages/jinja2/environment.py", line 1295, in render
    self.environment.handle_exception()
  File "/nfs/stak/users/kimh22/public_html/cs340_group39/NutriSphere_admin_panel/venv/lib64/python3.9/site-packages/jinja2/environment.py", line 942, in handle_exception
    raise rewrite_traceback_stack(source=source)
  File "/nfs/stak/users/kimh22/public_html/cs340_group39/NutriSphere_admin_panel/templates/index.html", line 16, in top-level template code
    <a href="{{ url_for('daily-trackers') }}">üóìÔ∏è Daily Trackers</a>
  File "/nfs/stak/users/kimh22/public_html/cs340_group39/NutriSphere_admin_panel/venv/lib64/python3.9/site-packages/flask/app.py", line 1121, in url_for
    return self.handle_url_build_error(error, endpoint, values)
  File "/nfs/stak/users/kimh22/public_html/cs340_group39/NutriSphere_admin_panel/venv/lib64/python3.9/site-packages/flask/app.py", line 1110, in url_for
    rv = url_adapter.build(  # type: ignore[union-attr]
  File "/nfs/stak/users/kimh22/public_html/cs340_group39/NutriSphere_admin_panel/venv/lib64/python3.9/site-packages/werkzeug/routing/map.py", line 924, in build
    raise BuildError(endpoint, values, method, self)
werkzeug.routing.exceptions.BuildError: Could not build url for endpoint 'daily-trackers'. Did you mean 'update_user' instead?
[2025-02-25 01:33:19,854] ERROR in app: Exception on / [GET]
Traceback (most recent call last):
  File "/nfs/stak/users/kimh22/public_html/cs340_group39/NutriSphere_admin_panel/venv/lib64/python3.9/site-packages/flask/app.py", line 1511, in wsgi_app
    response = self.full_dispatch_request()
  File "/nfs/stak/users/kimh22/public_html/cs340_group39/NutriSphere_admin_panel/venv/lib64/python3.9/site-packages/flask/app.py", line 919, in full_dispatch_request
    rv = self.handle_user_exception(e)
  File "/nfs/stak/users/kimh22/public_html/cs340_group39/NutriSphere_admin_panel/venv/lib64/python3.9/site-packages/flask/app.py", line 917, in full_dispatch_request
    rv = self.dispatch_request()
  File "/nfs/stak/users/kimh22/public_html/cs340_group39/NutriSphere_admin_panel/venv/lib64/python3.9/site-packages/flask/app.py", line 902, in dispatch_request
    return self.ensure_sync(self.view_functions[rule.endpoint])(**view_args)  # type: ignore[no-any-return]
  File "/nfs/stak/users/kimh22/public_html/cs340_group39/NutriSphere_admin_panel/app.py", line 18, in home
    return render_template("index.html")
  File "/nfs/stak/users/kimh22/public_html/cs340_group39/NutriSphere_admin_panel/venv/lib64/python3.9/site-packages/flask/templating.py", line 150, in render_template
    return _render(app, template, context)
  File "/nfs/stak/users/kimh22/public_html/cs340_group39/NutriSphere_admin_panel/venv/lib64/python3.9/site-packages/flask/templating.py", line 131, in _render
    rv = template.render(context)
  File "/nfs/stak/users/kimh22/public_html/cs340_group39/NutriSphere_admin_panel/venv/lib64/python3.9/site-packages/jinja2/environment.py", line 1295, in render
    self.environment.handle_exception()
  File "/nfs/stak/users/kimh22/public_html/cs340_group39/NutriSphere_admin_panel/venv/lib64/python3.9/site-packages/jinja2/environment.py", line 942, in handle_exception
    raise rewrite_traceback_stack(source=source)
  File "/nfs/stak/users/kimh22/public_html/cs340_group39/NutriSphere_admin_panel/templates/index.html", line 16, in top-level template code
    <a href="{{ url_for('daily-trackers') }}">üóìÔ∏è Daily Trackers</a>
  File "/nfs/stak/users/kimh22/public_html/cs340_group39/NutriSphere_admin_panel/venv/lib64/python3.9/site-packages/flask/app.py", line 1121, in url_for
    return self.handle_url_build_error(error, endpoint, values)
  File "/nfs/stak/users/kimh22/public_html/cs340_group39/NutriSphere_admin_panel/venv/lib64/python3.9/site-packages/flask/app.py", line 1110, in url_for
    rv = url_adapter.build(  # type: ignore[union-attr]
  File "/nfs/stak/users/kimh22/public_html/cs340_group39/NutriSphere_admin_panel/venv/lib64/python3.9/site-packages/werkzeug/routing/map.py", line 924, in build
    raise BuildError(endpoint, values, method, self)
werkzeug.routing.exceptions.BuildError: Could not build url for endpoint 'daily-trackers'. Did you mean 'update_user' instead?
[2025-02-25 01:33:20,006] ERROR in app: Exception on / [GET]
Traceback (most recent call last):
  File "/nfs/stak/users/kimh22/public_html/cs340_group39/NutriSphere_admin_panel/venv/lib64/python3.9/site-packages/flask/app.py", line 1511, in wsgi_app
    response = self.full_dispatch_request()
  File "/nfs/stak/users/kimh22/public_html/cs340_group39/NutriSphere_admin_panel/venv/lib64/python3.9/site-packages/flask/app.py", line 919, in full_dispatch_request
    rv = self.handle_user_exception(e)
  File "/nfs/stak/users/kimh22/public_html/cs340_group39/NutriSphere_admin_panel/venv/lib64/python3.9/site-packages/flask/app.py", line 917, in full_dispatch_request
    rv = self.dispatch_request()
  File "/nfs/stak/users/kimh22/public_html/cs340_group39/NutriSphere_admin_panel/venv/lib64/python3.9/site-packages/flask/app.py", line 902, in dispatch_request
    return self.ensure_sync(self.view_functions[rule.endpoint])(**view_args)  # type: ignore[no-any-return]
  File "/nfs/stak/users/kimh22/public_html/cs340_group39/NutriSphere_admin_panel/app.py", line 18, in home
    return render_template("index.html")
  File "/nfs/stak/users/kimh22/public_html/cs340_group39/NutriSphere_admin_panel/venv/lib64/python3.9/site-packages/flask/templating.py", line 150, in render_template
    return _render(app, template, context)
  File "/nfs/stak/users/kimh22/public_html/cs340_group39/NutriSphere_admin_panel/venv/lib64/python3.9/site-packages/flask/templating.py", line 131, in _render
    rv = template.render(context)
  File "/nfs/stak/users/kimh22/public_html/cs340_group39/NutriSphere_admin_panel/venv/lib64/python3.9/site-packages/jinja2/environment.py", line 1295, in render
    self.environment.handle_exception()
  File "/nfs/stak/users/kimh22/public_html/cs340_group39/NutriSphere_admin_panel/venv/lib64/python3.9/site-packages/jinja2/environment.py", line 942, in handle_exception
    raise rewrite_traceback_stack(source=source)
  File "/nfs/stak/users/kimh22/public_html/cs340_group39/NutriSphere_admin_panel/templates/index.html", line 16, in top-level template code
    <a href="{{ url_for('daily-trackers') }}">üóìÔ∏è Daily Trackers</a>
  File "/nfs/stak/users/kimh22/public_html/cs340_group39/NutriSphere_admin_panel/venv/lib64/python3.9/site-packages/flask/app.py", line 1121, in url_for
    return self.handle_url_build_error(error, endpoint, values)
  File "/nfs/stak/users/kimh22/public_html/cs340_group39/NutriSphere_admin_panel/venv/lib64/python3.9/site-packages/flask/app.py", line 1110, in url_for
    rv = url_adapter.build(  # type: ignore[union-attr]
  File "/nfs/stak/users/kimh22/public_html/cs340_group39/NutriSphere_admin_panel/venv/lib64/python3.9/site-packages/werkzeug/routing/map.py", line 924, in build
    raise BuildError(endpoint, values, method, self)
werkzeug.routing.exceptions.BuildError: Could not build url for endpoint 'daily-trackers'. Did you mean 'update_user' instead?
[2025-02-25 01:33:20,145] ERROR in app: Exception on / [GET]
Traceback (most recent call last):
  File "/nfs/stak/users/kimh22/public_html/cs340_group39/NutriSphere_admin_panel/venv/lib64/python3.9/site-packages/flask/app.py", line 1511, in wsgi_app
    response = self.full_dispatch_request()
  File "/nfs/stak/users/kimh22/public_html/cs340_group39/NutriSphere_admin_panel/venv/lib64/python3.9/site-packages/flask/app.py", line 919, in full_dispatch_request
    rv = self.handle_user_exception(e)
  File "/nfs/stak/users/kimh22/public_html/cs340_group39/NutriSphere_admin_panel/venv/lib64/python3.9/site-packages/flask/app.py", line 917, in full_dispatch_request
    rv = self.dispatch_request()
  File "/nfs/stak/users/kimh22/public_html/cs340_group39/NutriSphere_admin_panel/venv/lib64/python3.9/site-packages/flask/app.py", line 902, in dispatch_request
    return self.ensure_sync(self.view_functions[rule.endpoint])(**view_args)  # type: ignore[no-any-return]
  File "/nfs/stak/users/kimh22/public_html/cs340_group39/NutriSphere_admin_panel/app.py", line 18, in home
    return render_template("index.html")
  File "/nfs/stak/users/kimh22/public_html/cs340_group39/NutriSphere_admin_panel/venv/lib64/python3.9/site-packages/flask/templating.py", line 150, in render_template
    return _render(app, template, context)
  File "/nfs/stak/users/kimh22/public_html/cs340_group39/NutriSphere_admin_panel/venv/lib64/python3.9/site-packages/flask/templating.py", line 131, in _render
    rv = template.render(context)
  File "/nfs/stak/users/kimh22/public_html/cs340_group39/NutriSphere_admin_panel/venv/lib64/python3.9/site-packages/jinja2/environment.py", line 1295, in render
    self.environment.handle_exception()
  File "/nfs/stak/users/kimh22/public_html/cs340_group39/NutriSphere_admin_panel/venv/lib64/python3.9/site-packages/jinja2/environment.py", line 942, in handle_exception
    raise rewrite_traceback_stack(source=source)
  File "/nfs/stak/users/kimh22/public_html/cs340_group39/NutriSphere_admin_panel/templates/index.html", line 16, in top-level template code
    <a href="{{ url_for('daily-trackers') }}">üóìÔ∏è Daily Trackers</a>
  File "/nfs/stak/users/kimh22/public_html/cs340_group39/NutriSphere_admin_panel/venv/lib64/python3.9/site-packages/flask/app.py", line 1121, in url_for
    return self.handle_url_build_error(error, endpoint, values)
  File "/nfs/stak/users/kimh22/public_html/cs340_group39/NutriSphere_admin_panel/venv/lib64/python3.9/site-packages/flask/app.py", line 1110, in url_for
    rv = url_adapter.build(  # type: ignore[union-attr]
  File "/nfs/stak/users/kimh22/public_html/cs340_group39/NutriSphere_admin_panel/venv/lib64/python3.9/site-packages/werkzeug/routing/map.py", line 924, in build
    raise BuildError(endpoint, values, method, self)
werkzeug.routing.exceptions.BuildError: Could not build url for endpoint 'daily-trackers'. Did you mean 'update_user' instead?
[2025-02-25 01:33:20,302] ERROR in app: Exception on / [GET]
Traceback (most recent call last):
  File "/nfs/stak/users/kimh22/public_html/cs340_group39/NutriSphere_admin_panel/venv/lib64/python3.9/site-packages/flask/app.py", line 1511, in wsgi_app
    response = self.full_dispatch_request()
  File "/nfs/stak/users/kimh22/public_html/cs340_group39/NutriSphere_admin_panel/venv/lib64/python3.9/site-packages/flask/app.py", line 919, in full_dispatch_request
    rv = self.handle_user_exception(e)
  File "/nfs/stak/users/kimh22/public_html/cs340_group39/NutriSphere_admin_panel/venv/lib64/python3.9/site-packages/flask/app.py", line 917, in full_dispatch_request
    rv = self.dispatch_request()
  File "/nfs/stak/users/kimh22/public_html/cs340_group39/NutriSphere_admin_panel/venv/lib64/python3.9/site-packages/flask/app.py", line 902, in dispatch_request
    return self.ensure_sync(self.view_functions[rule.endpoint])(**view_args)  # type: ignore[no-any-return]
  File "/nfs/stak/users/kimh22/public_html/cs340_group39/NutriSphere_admin_panel/app.py", line 18, in home
    return render_template("index.html")
  File "/nfs/stak/users/kimh22/public_html/cs340_group39/NutriSphere_admin_panel/venv/lib64/python3.9/site-packages/flask/templating.py", line 150, in render_template
    return _render(app, template, context)
  File "/nfs/stak/users/kimh22/public_html/cs340_group39/NutriSphere_admin_panel/venv/lib64/python3.9/site-packages/flask/templating.py", line 131, in _render
    rv = template.render(context)
  File "/nfs/stak/users/kimh22/public_html/cs340_group39/NutriSphere_admin_panel/venv/lib64/python3.9/site-packages/jinja2/environment.py", line 1295, in render
    self.environment.handle_exception()
  File "/nfs/stak/users/kimh22/public_html/cs340_group39/NutriSphere_admin_panel/venv/lib64/python3.9/site-packages/jinja2/environment.py", line 942, in handle_exception
    raise rewrite_traceback_stack(source=source)
  File "/nfs/stak/users/kimh22/public_html/cs340_group39/NutriSphere_admin_panel/templates/index.html", line 16, in top-level template code
    <a href="{{ url_for('daily-trackers') }}">üóìÔ∏è Daily Trackers</a>
  File "/nfs/stak/users/kimh22/public_html/cs340_group39/NutriSphere_admin_panel/venv/lib64/python3.9/site-packages/flask/app.py", line 1121, in url_for
    return self.handle_url_build_error(error, endpoint, values)
  File "/nfs/stak/users/kimh22/public_html/cs340_group39/NutriSphere_admin_panel/venv/lib64/python3.9/site-packages/flask/app.py", line 1110, in url_for
    rv = url_adapter.build(  # type: ignore[union-attr]
  File "/nfs/stak/users/kimh22/public_html/cs340_group39/NutriSphere_admin_panel/venv/lib64/python3.9/site-packages/werkzeug/routing/map.py", line 924, in build
    raise BuildError(endpoint, values, method, self)
werkzeug.routing.exceptions.BuildError: Could not build url for endpoint 'daily-trackers'. Did you mean 'update_user' instead?
[2025-02-25 01:33:20,437] ERROR in app: Exception on / [GET]
Traceback (most recent call last):
  File "/nfs/stak/users/kimh22/public_html/cs340_group39/NutriSphere_admin_panel/venv/lib64/python3.9/site-packages/flask/app.py", line 1511, in wsgi_app
    response = self.full_dispatch_request()
  File "/nfs/stak/users/kimh22/public_html/cs340_group39/NutriSphere_admin_panel/venv/lib64/python3.9/site-packages/flask/app.py", line 919, in full_dispatch_request
    rv = self.handle_user_exception(e)
  File "/nfs/stak/users/kimh22/public_html/cs340_group39/NutriSphere_admin_panel/venv/lib64/python3.9/site-packages/flask/app.py", line 917, in full_dispatch_request
    rv = self.dispatch_request()
  File "/nfs/stak/users/kimh22/public_html/cs340_group39/NutriSphere_admin_panel/venv/lib64/python3.9/site-packages/flask/app.py", line 902, in dispatch_request
    return self.ensure_sync(self.view_functions[rule.endpoint])(**view_args)  # type: ignore[no-any-return]
  File "/nfs/stak/users/kimh22/public_html/cs340_group39/NutriSphere_admin_panel/app.py", line 18, in home
    return render_template("index.html")
  File "/nfs/stak/users/kimh22/public_html/cs340_group39/NutriSphere_admin_panel/venv/lib64/python3.9/site-packages/flask/templating.py", line 150, in render_template
    return _render(app, template, context)
  File "/nfs/stak/users/kimh22/public_html/cs340_group39/NutriSphere_admin_panel/venv/lib64/python3.9/site-packages/flask/templating.py", line 131, in _render
    rv = template.render(context)
  File "/nfs/stak/users/kimh22/public_html/cs340_group39/NutriSphere_admin_panel/venv/lib64/python3.9/site-packages/jinja2/environment.py", line 1295, in render
    self.environment.handle_exception()
  File "/nfs/stak/users/kimh22/public_html/cs340_group39/NutriSphere_admin_panel/venv/lib64/python3.9/site-packages/jinja2/environment.py", line 942, in handle_exception
    raise rewrite_traceback_stack(source=source)
  File "/nfs/stak/users/kimh22/public_html/cs340_group39/NutriSphere_admin_panel/templates/index.html", line 16, in top-level template code
    <a href="{{ url_for('daily-trackers') }}">üóìÔ∏è Daily Trackers</a>
  File "/nfs/stak/users/kimh22/public_html/cs340_group39/NutriSphere_admin_panel/venv/lib64/python3.9/site-packages/flask/app.py", line 1121, in url_for
    return self.handle_url_build_error(error, endpoint, values)
  File "/nfs/stak/users/kimh22/public_html/cs340_group39/NutriSphere_admin_panel/venv/lib64/python3.9/site-packages/flask/app.py", line 1110, in url_for
    rv = url_adapter.build(  # type: ignore[union-attr]
  File "/nfs/stak/users/kimh22/public_html/cs340_group39/NutriSphere_admin_panel/venv/lib64/python3.9/site-packages/werkzeug/routing/map.py", line 924, in build
    raise BuildError(endpoint, values, method, self)
werkzeug.routing.exceptions.BuildError: Could not build url for endpoint 'daily-trackers'. Did you mean 'update_user' instead?
[2025-02-25 01:33:20,625] ERROR in app: Exception on / [GET]
Traceback (most recent call last):
  File "/nfs/stak/users/kimh22/public_html/cs340_group39/NutriSphere_admin_panel/venv/lib64/python3.9/site-packages/flask/app.py", line 1511, in wsgi_app
    response = self.full_dispatch_request()
  File "/nfs/stak/users/kimh22/public_html/cs340_group39/NutriSphere_admin_panel/venv/lib64/python3.9/site-packages/flask/app.py", line 919, in full_dispatch_request
    rv = self.handle_user_exception(e)
  File "/nfs/stak/users/kimh22/public_html/cs340_group39/NutriSphere_admin_panel/venv/lib64/python3.9/site-packages/flask/app.py", line 917, in full_dispatch_request
    rv = self.dispatch_request()
  File "/nfs/stak/users/kimh22/public_html/cs340_group39/NutriSphere_admin_panel/venv/lib64/python3.9/site-packages/flask/app.py", line 902, in dispatch_request
    return self.ensure_sync(self.view_functions[rule.endpoint])(**view_args)  # type: ignore[no-any-return]
  File "/nfs/stak/users/kimh22/public_html/cs340_group39/NutriSphere_admin_panel/app.py", line 18, in home
    return render_template("index.html")
  File "/nfs/stak/users/kimh22/public_html/cs340_group39/NutriSphere_admin_panel/venv/lib64/python3.9/site-packages/flask/templating.py", line 150, in render_template
    return _render(app, template, context)
  File "/nfs/stak/users/kimh22/public_html/cs340_group39/NutriSphere_admin_panel/venv/lib64/python3.9/site-packages/flask/templating.py", line 131, in _render
    rv = template.render(context)
  File "/nfs/stak/users/kimh22/public_html/cs340_group39/NutriSphere_admin_panel/venv/lib64/python3.9/site-packages/jinja2/environment.py", line 1295, in render
    self.environment.handle_exception()
  File "/nfs/stak/users/kimh22/public_html/cs340_group39/NutriSphere_admin_panel/venv/lib64/python3.9/site-packages/jinja2/environment.py", line 942, in handle_exception
    raise rewrite_traceback_stack(source=source)
  File "/nfs/stak/users/kimh22/public_html/cs340_group39/NutriSphere_admin_panel/templates/index.html", line 16, in top-level template code
    <a href="{{ url_for('daily-trackers') }}">üóìÔ∏è Daily Trackers</a>
  File "/nfs/stak/users/kimh22/public_html/cs340_group39/NutriSphere_admin_panel/venv/lib64/python3.9/site-packages/flask/app.py", line 1121, in url_for
    return self.handle_url_build_error(error, endpoint, values)
  File "/nfs/stak/users/kimh22/public_html/cs340_group39/NutriSphere_admin_panel/venv/lib64/python3.9/site-packages/flask/app.py", line 1110, in url_for
    rv = url_adapter.build(  # type: ignore[union-attr]
  File "/nfs/stak/users/kimh22/public_html/cs340_group39/NutriSphere_admin_panel/venv/lib64/python3.9/site-packages/werkzeug/routing/map.py", line 924, in build
    raise BuildError(endpoint, values, method, self)
werkzeug.routing.exceptions.BuildError: Could not build url for endpoint 'daily-trackers'. Did you mean 'update_user' instead?
[2025-02-25 01:33:20,781] ERROR in app: Exception on / [GET]
Traceback (most recent call last):
  File "/nfs/stak/users/kimh22/public_html/cs340_group39/NutriSphere_admin_panel/venv/lib64/python3.9/site-packages/flask/app.py", line 1511, in wsgi_app
    response = self.full_dispatch_request()
  File "/nfs/stak/users/kimh22/public_html/cs340_group39/NutriSphere_admin_panel/venv/lib64/python3.9/site-packages/flask/app.py", line 919, in full_dispatch_request
    rv = self.handle_user_exception(e)
  File "/nfs/stak/users/kimh22/public_html/cs340_group39/NutriSphere_admin_panel/venv/lib64/python3.9/site-packages/flask/app.py", line 917, in full_dispatch_request
    rv = self.dispatch_request()
  File "/nfs/stak/users/kimh22/public_html/cs340_group39/NutriSphere_admin_panel/venv/lib64/python3.9/site-packages/flask/app.py", line 902, in dispatch_request
    return self.ensure_sync(self.view_functions[rule.endpoint])(**view_args)  # type: ignore[no-any-return]
  File "/nfs/stak/users/kimh22/public_html/cs340_group39/NutriSphere_admin_panel/app.py", line 18, in home
    return render_template("index.html")
  File "/nfs/stak/users/kimh22/public_html/cs340_group39/NutriSphere_admin_panel/venv/lib64/python3.9/site-packages/flask/templating.py", line 150, in render_template
    return _render(app, template, context)
  File "/nfs/stak/users/kimh22/public_html/cs340_group39/NutriSphere_admin_panel/venv/lib64/python3.9/site-packages/flask/templating.py", line 131, in _render
    rv = template.render(context)
  File "/nfs/stak/users/kimh22/public_html/cs340_group39/NutriSphere_admin_panel/venv/lib64/python3.9/site-packages/jinja2/environment.py", line 1295, in render
    self.environment.handle_exception()
  File "/nfs/stak/users/kimh22/public_html/cs340_group39/NutriSphere_admin_panel/venv/lib64/python3.9/site-packages/jinja2/environment.py", line 942, in handle_exception
    raise rewrite_traceback_stack(source=source)
  File "/nfs/stak/users/kimh22/public_html/cs340_group39/NutriSphere_admin_panel/templates/index.html", line 16, in top-level template code
    <a href="{{ url_for('daily-trackers') }}">üóìÔ∏è Daily Trackers</a>
  File "/nfs/stak/users/kimh22/public_html/cs340_group39/NutriSphere_admin_panel/venv/lib64/python3.9/site-packages/flask/app.py", line 1121, in url_for
    return self.handle_url_build_error(error, endpoint, values)
  File "/nfs/stak/users/kimh22/public_html/cs340_group39/NutriSphere_admin_panel/venv/lib64/python3.9/site-packages/flask/app.py", line 1110, in url_for
    rv = url_adapter.build(  # type: ignore[union-attr]
  File "/nfs/stak/users/kimh22/public_html/cs340_group39/NutriSphere_admin_panel/venv/lib64/python3.9/site-packages/werkzeug/routing/map.py", line 924, in build
    raise BuildError(endpoint, values, method, self)
werkzeug.routing.exceptions.BuildError: Could not build url for endpoint 'daily-trackers'. Did you mean 'update_user' instead?
[2025-02-25 01:33:51 -0800] [2636589] [CRITICAL] WORKER TIMEOUT (pid:2636596)
[2025-02-25 01:33:51 -0800] [2636596] [ERROR] Error handling request (no URI read)
Traceback (most recent call last):
  File "/nfs/stak/users/kimh22/public_html/cs340_group39/NutriSphere_admin_panel/venv/lib64/python3.9/site-packages/gunicorn/workers/sync.py", line 133, in handle
    req = next(parser)
  File "/nfs/stak/users/kimh22/public_html/cs340_group39/NutriSphere_admin_panel/venv/lib64/python3.9/site-packages/gunicorn/http/parser.py", line 41, in __next__
    self.mesg = self.mesg_class(self.cfg, self.unreader, self.source_addr, self.req_count)
  File "/nfs/stak/users/kimh22/public_html/cs340_group39/NutriSphere_admin_panel/venv/lib64/python3.9/site-packages/gunicorn/http/message.py", line 259, in __init__
    super().__init__(cfg, unreader, peer_addr)
  File "/nfs/stak/users/kimh22/public_html/cs340_group39/NutriSphere_admin_panel/venv/lib64/python3.9/site-packages/gunicorn/http/message.py", line 60, in __init__
    unused = self.parse(self.unreader)
  File "/nfs/stak/users/kimh22/public_html/cs340_group39/NutriSphere_admin_panel/venv/lib64/python3.9/site-packages/gunicorn/http/message.py", line 271, in parse
    self.get_data(unreader, buf, stop=True)
  File "/nfs/stak/users/kimh22/public_html/cs340_group39/NutriSphere_admin_panel/venv/lib64/python3.9/site-packages/gunicorn/http/message.py", line 262, in get_data
    data = unreader.read()
  File "/nfs/stak/users/kimh22/public_html/cs340_group39/NutriSphere_admin_panel/venv/lib64/python3.9/site-packages/gunicorn/http/unreader.py", line 36, in read
    d = self.chunk()
  File "/nfs/stak/users/kimh22/public_html/cs340_group39/NutriSphere_admin_panel/venv/lib64/python3.9/site-packages/gunicorn/http/unreader.py", line 63, in chunk
    return self.sock.recv(self.mxchunk)
  File "/nfs/stak/users/kimh22/public_html/cs340_group39/NutriSphere_admin_panel/venv/lib64/python3.9/site-packages/gunicorn/workers/base.py", line 204, in handle_abort
    sys.exit(1)
SystemExit: 1
[2025-02-25 01:33:51 -0800] [2636596] [INFO] Worker exiting (pid: 2636596)
[2025-02-25 01:33:51 -0800] [2636836] [INFO] Booting worker with pid: 2636836
[2025-02-25 01:39:24 -0800] [2636836] [INFO] Worker exiting (pid: 2636836)
[2025-02-25 01:39:24 -0800] [2636589] [INFO] Handling signal: term
[2025-02-25 01:39:24 -0800] [2636589] [ERROR] Worker (pid:2636836) was sent SIGTERM!
[2025-02-25 01:39:24 -0800] [2636589] [INFO] Shutting down: Master
[2025-02-25 01:39:24 -0800] [2637907] [INFO] Starting gunicorn 23.0.0
[2025-02-25 01:39:24 -0800] [2637907] [INFO] Listening at: http://0.0.0.0:65216 (2637907)
[2025-02-25 01:39:24 -0800] [2637907] [INFO] Using worker: sync
[2025-02-25 01:39:24 -0800] [2637910] [INFO] Booting worker with pid: 2637910
[2025-02-25 01:39:33,046] ERROR in app: Exception on / [GET]
Traceback (most recent call last):
  File "/nfs/stak/users/kimh22/public_html/cs340_group39/NutriSphere_admin_panel/venv/lib64/python3.9/site-packages/flask/app.py", line 1511, in wsgi_app
    response = self.full_dispatch_request()
  File "/nfs/stak/users/kimh22/public_html/cs340_group39/NutriSphere_admin_panel/venv/lib64/python3.9/site-packages/flask/app.py", line 919, in full_dispatch_request
    rv = self.handle_user_exception(e)
  File "/nfs/stak/users/kimh22/public_html/cs340_group39/NutriSphere_admin_panel/venv/lib64/python3.9/site-packages/flask/app.py", line 917, in full_dispatch_request
    rv = self.dispatch_request()
  File "/nfs/stak/users/kimh22/public_html/cs340_group39/NutriSphere_admin_panel/venv/lib64/python3.9/site-packages/flask/app.py", line 902, in dispatch_request
    return self.ensure_sync(self.view_functions[rule.endpoint])(**view_args)  # type: ignore[no-any-return]
  File "/nfs/stak/users/kimh22/public_html/cs340_group39/NutriSphere_admin_panel/app.py", line 19, in home
    return render_template("index.html")
  File "/nfs/stak/users/kimh22/public_html/cs340_group39/NutriSphere_admin_panel/venv/lib64/python3.9/site-packages/flask/templating.py", line 150, in render_template
    return _render(app, template, context)
  File "/nfs/stak/users/kimh22/public_html/cs340_group39/NutriSphere_admin_panel/venv/lib64/python3.9/site-packages/flask/templating.py", line 131, in _render
    rv = template.render(context)
  File "/nfs/stak/users/kimh22/public_html/cs340_group39/NutriSphere_admin_panel/venv/lib64/python3.9/site-packages/jinja2/environment.py", line 1295, in render
    self.environment.handle_exception()
  File "/nfs/stak/users/kimh22/public_html/cs340_group39/NutriSphere_admin_panel/venv/lib64/python3.9/site-packages/jinja2/environment.py", line 942, in handle_exception
    raise rewrite_traceback_stack(source=source)
  File "/nfs/stak/users/kimh22/public_html/cs340_group39/NutriSphere_admin_panel/templates/index.html", line 16, in top-level template code
    <a href="{{ url_for('daily-trackers') }}">üóìÔ∏è Daily Trackers</a>
  File "/nfs/stak/users/kimh22/public_html/cs340_group39/NutriSphere_admin_panel/venv/lib64/python3.9/site-packages/flask/app.py", line 1121, in url_for
    return self.handle_url_build_error(error, endpoint, values)
  File "/nfs/stak/users/kimh22/public_html/cs340_group39/NutriSphere_admin_panel/venv/lib64/python3.9/site-packages/flask/app.py", line 1110, in url_for
    rv = url_adapter.build(  # type: ignore[union-attr]
  File "/nfs/stak/users/kimh22/public_html/cs340_group39/NutriSphere_admin_panel/venv/lib64/python3.9/site-packages/werkzeug/routing/map.py", line 924, in build
    raise BuildError(endpoint, values, method, self)
werkzeug.routing.exceptions.BuildError: Could not build url for endpoint 'daily-trackers'. Did you mean 'daily_trackers' instead?
[2025-02-25 01:39:36,309] ERROR in app: Exception on / [GET]
Traceback (most recent call last):
  File "/nfs/stak/users/kimh22/public_html/cs340_group39/NutriSphere_admin_panel/venv/lib64/python3.9/site-packages/flask/app.py", line 1511, in wsgi_app
    response = self.full_dispatch_request()
  File "/nfs/stak/users/kimh22/public_html/cs340_group39/NutriSphere_admin_panel/venv/lib64/python3.9/site-packages/flask/app.py", line 919, in full_dispatch_request
    rv = self.handle_user_exception(e)
  File "/nfs/stak/users/kimh22/public_html/cs340_group39/NutriSphere_admin_panel/venv/lib64/python3.9/site-packages/flask/app.py", line 917, in full_dispatch_request
    rv = self.dispatch_request()
  File "/nfs/stak/users/kimh22/public_html/cs340_group39/NutriSphere_admin_panel/venv/lib64/python3.9/site-packages/flask/app.py", line 902, in dispatch_request
    return self.ensure_sync(self.view_functions[rule.endpoint])(**view_args)  # type: ignore[no-any-return]
  File "/nfs/stak/users/kimh22/public_html/cs340_group39/NutriSphere_admin_panel/app.py", line 19, in home
    return render_template("index.html")
  File "/nfs/stak/users/kimh22/public_html/cs340_group39/NutriSphere_admin_panel/venv/lib64/python3.9/site-packages/flask/templating.py", line 150, in render_template
    return _render(app, template, context)
  File "/nfs/stak/users/kimh22/public_html/cs340_group39/NutriSphere_admin_panel/venv/lib64/python3.9/site-packages/flask/templating.py", line 131, in _render
    rv = template.render(context)
  File "/nfs/stak/users/kimh22/public_html/cs340_group39/NutriSphere_admin_panel/venv/lib64/python3.9/site-packages/jinja2/environment.py", line 1295, in render
    self.environment.handle_exception()
  File "/nfs/stak/users/kimh22/public_html/cs340_group39/NutriSphere_admin_panel/venv/lib64/python3.9/site-packages/jinja2/environment.py", line 942, in handle_exception
    raise rewrite_traceback_stack(source=source)
  File "/nfs/stak/users/kimh22/public_html/cs340_group39/NutriSphere_admin_panel/templates/index.html", line 16, in top-level template code
    <a href="{{ url_for('daily-trackers') }}">üóìÔ∏è Daily Trackers</a>
  File "/nfs/stak/users/kimh22/public_html/cs340_group39/NutriSphere_admin_panel/venv/lib64/python3.9/site-packages/flask/app.py", line 1121, in url_for
    return self.handle_url_build_error(error, endpoint, values)
  File "/nfs/stak/users/kimh22/public_html/cs340_group39/NutriSphere_admin_panel/venv/lib64/python3.9/site-packages/flask/app.py", line 1110, in url_for
    rv = url_adapter.build(  # type: ignore[union-attr]
  File "/nfs/stak/users/kimh22/public_html/cs340_group39/NutriSphere_admin_panel/venv/lib64/python3.9/site-packages/werkzeug/routing/map.py", line 924, in build
    raise BuildError(endpoint, values, method, self)
werkzeug.routing.exceptions.BuildError: Could not build url for endpoint 'daily-trackers'. Did you mean 'daily_trackers' instead?
[2025-02-25 01:40:07 -0800] [2637907] [CRITICAL] WORKER TIMEOUT (pid:2637910)
[2025-02-25 01:40:07 -0800] [2637910] [ERROR] Error handling request (no URI read)
Traceback (most recent call last):
  File "/nfs/stak/users/kimh22/public_html/cs340_group39/NutriSphere_admin_panel/venv/lib64/python3.9/site-packages/gunicorn/workers/sync.py", line 133, in handle
    req = next(parser)
  File "/nfs/stak/users/kimh22/public_html/cs340_group39/NutriSphere_admin_panel/venv/lib64/python3.9/site-packages/gunicorn/http/parser.py", line 41, in __next__
    self.mesg = self.mesg_class(self.cfg, self.unreader, self.source_addr, self.req_count)
  File "/nfs/stak/users/kimh22/public_html/cs340_group39/NutriSphere_admin_panel/venv/lib64/python3.9/site-packages/gunicorn/http/message.py", line 259, in __init__
    super().__init__(cfg, unreader, peer_addr)
  File "/nfs/stak/users/kimh22/public_html/cs340_group39/NutriSphere_admin_panel/venv/lib64/python3.9/site-packages/gunicorn/http/message.py", line 60, in __init__
    unused = self.parse(self.unreader)
  File "/nfs/stak/users/kimh22/public_html/cs340_group39/NutriSphere_admin_panel/venv/lib64/python3.9/site-packages/gunicorn/http/message.py", line 271, in parse
    self.get_data(unreader, buf, stop=True)
  File "/nfs/stak/users/kimh22/public_html/cs340_group39/NutriSphere_admin_panel/venv/lib64/python3.9/site-packages/gunicorn/http/message.py", line 262, in get_data
    data = unreader.read()
  File "/nfs/stak/users/kimh22/public_html/cs340_group39/NutriSphere_admin_panel/venv/lib64/python3.9/site-packages/gunicorn/http/unreader.py", line 36, in read
    d = self.chunk()
  File "/nfs/stak/users/kimh22/public_html/cs340_group39/NutriSphere_admin_panel/venv/lib64/python3.9/site-packages/gunicorn/http/unreader.py", line 63, in chunk
    return self.sock.recv(self.mxchunk)
  File "/nfs/stak/users/kimh22/public_html/cs340_group39/NutriSphere_admin_panel/venv/lib64/python3.9/site-packages/gunicorn/workers/base.py", line 204, in handle_abort
    sys.exit(1)
SystemExit: 1
[2025-02-25 01:40:07 -0800] [2637910] [INFO] Worker exiting (pid: 2637910)
[2025-02-25 01:40:07 -0800] [2638061] [INFO] Booting worker with pid: 2638061
[2025-02-25 01:41:22 -0800] [2638061] [INFO] Worker exiting (pid: 2638061)
[2025-02-25 01:41:22 -0800] [2637907] [INFO] Handling signal: term
[2025-02-25 01:41:22 -0800] [2637907] [ERROR] Worker (pid:2638061) was sent SIGTERM!
[2025-02-25 01:41:22 -0800] [2637907] [INFO] Shutting down: Master
[2025-02-25 01:42:31 -0800] [2638387] [INFO] Starting gunicorn 23.0.0
[2025-02-25 01:42:31 -0800] [2638387] [INFO] Listening at: http://0.0.0.0:65216 (2638387)
[2025-02-25 01:42:31 -0800] [2638387] [INFO] Using worker: sync
[2025-02-25 01:42:31 -0800] [2638390] [INFO] Booting worker with pid: 2638390
[2025-02-25 01:42:31 -0800] [2638397] [INFO] Booting worker with pid: 2638397
[2025-02-25 01:42:33,714] ERROR in app: Exception on / [GET]
Traceback (most recent call last):
  File "/nfs/stak/users/kimh22/public_html/cs340_group39/NutriSphere_admin_panel/venv/lib64/python3.9/site-packages/flask/app.py", line 1511, in wsgi_app
    response = self.full_dispatch_request()
  File "/nfs/stak/users/kimh22/public_html/cs340_group39/NutriSphere_admin_panel/venv/lib64/python3.9/site-packages/flask/app.py", line 919, in full_dispatch_request
    rv = self.handle_user_exception(e)
  File "/nfs/stak/users/kimh22/public_html/cs340_group39/NutriSphere_admin_panel/venv/lib64/python3.9/site-packages/flask/app.py", line 917, in full_dispatch_request
    rv = self.dispatch_request()
  File "/nfs/stak/users/kimh22/public_html/cs340_group39/NutriSphere_admin_panel/venv/lib64/python3.9/site-packages/flask/app.py", line 902, in dispatch_request
    return self.ensure_sync(self.view_functions[rule.endpoint])(**view_args)  # type: ignore[no-any-return]
  File "/nfs/stak/users/kimh22/public_html/cs340_group39/NutriSphere_admin_panel/app.py", line 19, in home
    return render_template("index.html")
  File "/nfs/stak/users/kimh22/public_html/cs340_group39/NutriSphere_admin_panel/venv/lib64/python3.9/site-packages/flask/templating.py", line 150, in render_template
    return _render(app, template, context)
  File "/nfs/stak/users/kimh22/public_html/cs340_group39/NutriSphere_admin_panel/venv/lib64/python3.9/site-packages/flask/templating.py", line 131, in _render
    rv = template.render(context)
  File "/nfs/stak/users/kimh22/public_html/cs340_group39/NutriSphere_admin_panel/venv/lib64/python3.9/site-packages/jinja2/environment.py", line 1295, in render
    self.environment.handle_exception()
  File "/nfs/stak/users/kimh22/public_html/cs340_group39/NutriSphere_admin_panel/venv/lib64/python3.9/site-packages/jinja2/environment.py", line 942, in handle_exception
    raise rewrite_traceback_stack(source=source)
  File "/nfs/stak/users/kimh22/public_html/cs340_group39/NutriSphere_admin_panel/templates/index.html", line 16, in top-level template code
    <a href="{{ url_for('daily-trackers') }}">üóìÔ∏è Daily Trackers</a>
  File "/nfs/stak/users/kimh22/public_html/cs340_group39/NutriSphere_admin_panel/venv/lib64/python3.9/site-packages/flask/app.py", line 1121, in url_for
    return self.handle_url_build_error(error, endpoint, values)
  File "/nfs/stak/users/kimh22/public_html/cs340_group39/NutriSphere_admin_panel/venv/lib64/python3.9/site-packages/flask/app.py", line 1110, in url_for
    rv = url_adapter.build(  # type: ignore[union-attr]
  File "/nfs/stak/users/kimh22/public_html/cs340_group39/NutriSphere_admin_panel/venv/lib64/python3.9/site-packages/werkzeug/routing/map.py", line 924, in build
    raise BuildError(endpoint, values, method, self)
werkzeug.routing.exceptions.BuildError: Could not build url for endpoint 'daily-trackers'. Did you mean 'daily_trackers' instead?
[2025-02-25 01:42:34,324] ERROR in app: Exception on / [GET]
Traceback (most recent call last):
  File "/nfs/stak/users/kimh22/public_html/cs340_group39/NutriSphere_admin_panel/venv/lib64/python3.9/site-packages/flask/app.py", line 1511, in wsgi_app
    response = self.full_dispatch_request()
  File "/nfs/stak/users/kimh22/public_html/cs340_group39/NutriSphere_admin_panel/venv/lib64/python3.9/site-packages/flask/app.py", line 919, in full_dispatch_request
    rv = self.handle_user_exception(e)
  File "/nfs/stak/users/kimh22/public_html/cs340_group39/NutriSphere_admin_panel/venv/lib64/python3.9/site-packages/flask/app.py", line 917, in full_dispatch_request
    rv = self.dispatch_request()
  File "/nfs/stak/users/kimh22/public_html/cs340_group39/NutriSphere_admin_panel/venv/lib64/python3.9/site-packages/flask/app.py", line 902, in dispatch_request
    return self.ensure_sync(self.view_functions[rule.endpoint])(**view_args)  # type: ignore[no-any-return]
  File "/nfs/stak/users/kimh22/public_html/cs340_group39/NutriSphere_admin_panel/app.py", line 19, in home
    return render_template("index.html")
  File "/nfs/stak/users/kimh22/public_html/cs340_group39/NutriSphere_admin_panel/venv/lib64/python3.9/site-packages/flask/templating.py", line 150, in render_template
    return _render(app, template, context)
  File "/nfs/stak/users/kimh22/public_html/cs340_group39/NutriSphere_admin_panel/venv/lib64/python3.9/site-packages/flask/templating.py", line 131, in _render
    rv = template.render(context)
  File "/nfs/stak/users/kimh22/public_html/cs340_group39/NutriSphere_admin_panel/venv/lib64/python3.9/site-packages/jinja2/environment.py", line 1295, in render
    self.environment.handle_exception()
  File "/nfs/stak/users/kimh22/public_html/cs340_group39/NutriSphere_admin_panel/venv/lib64/python3.9/site-packages/jinja2/environment.py", line 942, in handle_exception
    raise rewrite_traceback_stack(source=source)
  File "/nfs/stak/users/kimh22/public_html/cs340_group39/NutriSphere_admin_panel/templates/index.html", line 16, in top-level template code
    <a href="{{ url_for('daily-trackers') }}">üóìÔ∏è Daily Trackers</a>
  File "/nfs/stak/users/kimh22/public_html/cs340_group39/NutriSphere_admin_panel/venv/lib64/python3.9/site-packages/flask/app.py", line 1121, in url_for
    return self.handle_url_build_error(error, endpoint, values)
  File "/nfs/stak/users/kimh22/public_html/cs340_group39/NutriSphere_admin_panel/venv/lib64/python3.9/site-packages/flask/app.py", line 1110, in url_for
    rv = url_adapter.build(  # type: ignore[union-attr]
  File "/nfs/stak/users/kimh22/public_html/cs340_group39/NutriSphere_admin_panel/venv/lib64/python3.9/site-packages/werkzeug/routing/map.py", line 924, in build
    raise BuildError(endpoint, values, method, self)
werkzeug.routing.exceptions.BuildError: Could not build url for endpoint 'daily-trackers'. Did you mean 'daily_trackers' instead?
[2025-02-25 01:42:34,477] ERROR in app: Exception on / [GET]
Traceback (most recent call last):
  File "/nfs/stak/users/kimh22/public_html/cs340_group39/NutriSphere_admin_panel/venv/lib64/python3.9/site-packages/flask/app.py", line 1511, in wsgi_app
    response = self.full_dispatch_request()
  File "/nfs/stak/users/kimh22/public_html/cs340_group39/NutriSphere_admin_panel/venv/lib64/python3.9/site-packages/flask/app.py", line 919, in full_dispatch_request
    rv = self.handle_user_exception(e)
  File "/nfs/stak/users/kimh22/public_html/cs340_group39/NutriSphere_admin_panel/venv/lib64/python3.9/site-packages/flask/app.py", line 917, in full_dispatch_request
    rv = self.dispatch_request()
  File "/nfs/stak/users/kimh22/public_html/cs340_group39/NutriSphere_admin_panel/venv/lib64/python3.9/site-packages/flask/app.py", line 902, in dispatch_request
    return self.ensure_sync(self.view_functions[rule.endpoint])(**view_args)  # type: ignore[no-any-return]
  File "/nfs/stak/users/kimh22/public_html/cs340_group39/NutriSphere_admin_panel/app.py", line 19, in home
    return render_template("index.html")
  File "/nfs/stak/users/kimh22/public_html/cs340_group39/NutriSphere_admin_panel/venv/lib64/python3.9/site-packages/flask/templating.py", line 150, in render_template
    return _render(app, template, context)
  File "/nfs/stak/users/kimh22/public_html/cs340_group39/NutriSphere_admin_panel/venv/lib64/python3.9/site-packages/flask/templating.py", line 131, in _render
    rv = template.render(context)
  File "/nfs/stak/users/kimh22/public_html/cs340_group39/NutriSphere_admin_panel/venv/lib64/python3.9/site-packages/jinja2/environment.py", line 1295, in render
    self.environment.handle_exception()
  File "/nfs/stak/users/kimh22/public_html/cs340_group39/NutriSphere_admin_panel/venv/lib64/python3.9/site-packages/jinja2/environment.py", line 942, in handle_exception
    raise rewrite_traceback_stack(source=source)
  File "/nfs/stak/users/kimh22/public_html/cs340_group39/NutriSphere_admin_panel/templates/index.html", line 16, in top-level template code
    <a href="{{ url_for('daily-trackers') }}">üóìÔ∏è Daily Trackers</a>
  File "/nfs/stak/users/kimh22/public_html/cs340_group39/NutriSphere_admin_panel/venv/lib64/python3.9/site-packages/flask/app.py", line 1121, in url_for
    return self.handle_url_build_error(error, endpoint, values)
  File "/nfs/stak/users/kimh22/public_html/cs340_group39/NutriSphere_admin_panel/venv/lib64/python3.9/site-packages/flask/app.py", line 1110, in url_for
    rv = url_adapter.build(  # type: ignore[union-attr]
  File "/nfs/stak/users/kimh22/public_html/cs340_group39/NutriSphere_admin_panel/venv/lib64/python3.9/site-packages/werkzeug/routing/map.py", line 924, in build
    raise BuildError(endpoint, values, method, self)
werkzeug.routing.exceptions.BuildError: Could not build url for endpoint 'daily-trackers'. Did you mean 'daily_trackers' instead?
[2025-02-25 01:42:34,627] ERROR in app: Exception on / [GET]
Traceback (most recent call last):
  File "/nfs/stak/users/kimh22/public_html/cs340_group39/NutriSphere_admin_panel/venv/lib64/python3.9/site-packages/flask/app.py", line 1511, in wsgi_app
    response = self.full_dispatch_request()
  File "/nfs/stak/users/kimh22/public_html/cs340_group39/NutriSphere_admin_panel/venv/lib64/python3.9/site-packages/flask/app.py", line 919, in full_dispatch_request
    rv = self.handle_user_exception(e)
  File "/nfs/stak/users/kimh22/public_html/cs340_group39/NutriSphere_admin_panel/venv/lib64/python3.9/site-packages/flask/app.py", line 917, in full_dispatch_request
    rv = self.dispatch_request()
  File "/nfs/stak/users/kimh22/public_html/cs340_group39/NutriSphere_admin_panel/venv/lib64/python3.9/site-packages/flask/app.py", line 902, in dispatch_request
    return self.ensure_sync(self.view_functions[rule.endpoint])(**view_args)  # type: ignore[no-any-return]
  File "/nfs/stak/users/kimh22/public_html/cs340_group39/NutriSphere_admin_panel/app.py", line 19, in home
    return render_template("index.html")
  File "/nfs/stak/users/kimh22/public_html/cs340_group39/NutriSphere_admin_panel/venv/lib64/python3.9/site-packages/flask/templating.py", line 150, in render_template
    return _render(app, template, context)
  File "/nfs/stak/users/kimh22/public_html/cs340_group39/NutriSphere_admin_panel/venv/lib64/python3.9/site-packages/flask/templating.py", line 131, in _render
    rv = template.render(context)
  File "/nfs/stak/users/kimh22/public_html/cs340_group39/NutriSphere_admin_panel/venv/lib64/python3.9/site-packages/jinja2/environment.py", line 1295, in render
    self.environment.handle_exception()
  File "/nfs/stak/users/kimh22/public_html/cs340_group39/NutriSphere_admin_panel/venv/lib64/python3.9/site-packages/jinja2/environment.py", line 942, in handle_exception
    raise rewrite_traceback_stack(source=source)
  File "/nfs/stak/users/kimh22/public_html/cs340_group39/NutriSphere_admin_panel/templates/index.html", line 16, in top-level template code
    <a href="{{ url_for('daily-trackers') }}">üóìÔ∏è Daily Trackers</a>
  File "/nfs/stak/users/kimh22/public_html/cs340_group39/NutriSphere_admin_panel/venv/lib64/python3.9/site-packages/flask/app.py", line 1121, in url_for
    return self.handle_url_build_error(error, endpoint, values)
  File "/nfs/stak/users/kimh22/public_html/cs340_group39/NutriSphere_admin_panel/venv/lib64/python3.9/site-packages/flask/app.py", line 1110, in url_for
    rv = url_adapter.build(  # type: ignore[union-attr]
  File "/nfs/stak/users/kimh22/public_html/cs340_group39/NutriSphere_admin_panel/venv/lib64/python3.9/site-packages/werkzeug/routing/map.py", line 924, in build
    raise BuildError(endpoint, values, method, self)
werkzeug.routing.exceptions.BuildError: Could not build url for endpoint 'daily-trackers'. Did you mean 'daily_trackers' instead?
[2025-02-25 01:42:34,785] ERROR in app: Exception on / [GET]
Traceback (most recent call last):
  File "/nfs/stak/users/kimh22/public_html/cs340_group39/NutriSphere_admin_panel/venv/lib64/python3.9/site-packages/flask/app.py", line 1511, in wsgi_app
    response = self.full_dispatch_request()
  File "/nfs/stak/users/kimh22/public_html/cs340_group39/NutriSphere_admin_panel/venv/lib64/python3.9/site-packages/flask/app.py", line 919, in full_dispatch_request
    rv = self.handle_user_exception(e)
  File "/nfs/stak/users/kimh22/public_html/cs340_group39/NutriSphere_admin_panel/venv/lib64/python3.9/site-packages/flask/app.py", line 917, in full_dispatch_request
    rv = self.dispatch_request()
  File "/nfs/stak/users/kimh22/public_html/cs340_group39/NutriSphere_admin_panel/venv/lib64/python3.9/site-packages/flask/app.py", line 902, in dispatch_request
    return self.ensure_sync(self.view_functions[rule.endpoint])(**view_args)  # type: ignore[no-any-return]
  File "/nfs/stak/users/kimh22/public_html/cs340_group39/NutriSphere_admin_panel/app.py", line 19, in home
    return render_template("index.html")
  File "/nfs/stak/users/kimh22/public_html/cs340_group39/NutriSphere_admin_panel/venv/lib64/python3.9/site-packages/flask/templating.py", line 150, in render_template
    return _render(app, template, context)
  File "/nfs/stak/users/kimh22/public_html/cs340_group39/NutriSphere_admin_panel/venv/lib64/python3.9/site-packages/flask/templating.py", line 131, in _render
    rv = template.render(context)
  File "/nfs/stak/users/kimh22/public_html/cs340_group39/NutriSphere_admin_panel/venv/lib64/python3.9/site-packages/jinja2/environment.py", line 1295, in render
    self.environment.handle_exception()
  File "/nfs/stak/users/kimh22/public_html/cs340_group39/NutriSphere_admin_panel/venv/lib64/python3.9/site-packages/jinja2/environment.py", line 942, in handle_exception
    raise rewrite_traceback_stack(source=source)
  File "/nfs/stak/users/kimh22/public_html/cs340_group39/NutriSphere_admin_panel/templates/index.html", line 16, in top-level template code
    <a href="{{ url_for('daily-trackers') }}">üóìÔ∏è Daily Trackers</a>
  File "/nfs/stak/users/kimh22/public_html/cs340_group39/NutriSphere_admin_panel/venv/lib64/python3.9/site-packages/flask/app.py", line 1121, in url_for
    return self.handle_url_build_error(error, endpoint, values)
  File "/nfs/stak/users/kimh22/public_html/cs340_group39/NutriSphere_admin_panel/venv/lib64/python3.9/site-packages/flask/app.py", line 1110, in url_for
    rv = url_adapter.build(  # type: ignore[union-attr]
  File "/nfs/stak/users/kimh22/public_html/cs340_group39/NutriSphere_admin_panel/venv/lib64/python3.9/site-packages/werkzeug/routing/map.py", line 924, in build
    raise BuildError(endpoint, values, method, self)
werkzeug.routing.exceptions.BuildError: Could not build url for endpoint 'daily-trackers'. Did you mean 'daily_trackers' instead?
[2025-02-25 01:42:34,941] ERROR in app: Exception on / [GET]
Traceback (most recent call last):
  File "/nfs/stak/users/kimh22/public_html/cs340_group39/NutriSphere_admin_panel/venv/lib64/python3.9/site-packages/flask/app.py", line 1511, in wsgi_app
    response = self.full_dispatch_request()
  File "/nfs/stak/users/kimh22/public_html/cs340_group39/NutriSphere_admin_panel/venv/lib64/python3.9/site-packages/flask/app.py", line 919, in full_dispatch_request
    rv = self.handle_user_exception(e)
  File "/nfs/stak/users/kimh22/public_html/cs340_group39/NutriSphere_admin_panel/venv/lib64/python3.9/site-packages/flask/app.py", line 917, in full_dispatch_request
    rv = self.dispatch_request()
  File "/nfs/stak/users/kimh22/public_html/cs340_group39/NutriSphere_admin_panel/venv/lib64/python3.9/site-packages/flask/app.py", line 902, in dispatch_request
    return self.ensure_sync(self.view_functions[rule.endpoint])(**view_args)  # type: ignore[no-any-return]
  File "/nfs/stak/users/kimh22/public_html/cs340_group39/NutriSphere_admin_panel/app.py", line 19, in home
    return render_template("index.html")
  File "/nfs/stak/users/kimh22/public_html/cs340_group39/NutriSphere_admin_panel/venv/lib64/python3.9/site-packages/flask/templating.py", line 150, in render_template
    return _render(app, template, context)
  File "/nfs/stak/users/kimh22/public_html/cs340_group39/NutriSphere_admin_panel/venv/lib64/python3.9/site-packages/flask/templating.py", line 131, in _render
    rv = template.render(context)
  File "/nfs/stak/users/kimh22/public_html/cs340_group39/NutriSphere_admin_panel/venv/lib64/python3.9/site-packages/jinja2/environment.py", line 1295, in render
    self.environment.handle_exception()
  File "/nfs/stak/users/kimh22/public_html/cs340_group39/NutriSphere_admin_panel/venv/lib64/python3.9/site-packages/jinja2/environment.py", line 942, in handle_exception
    raise rewrite_traceback_stack(source=source)
  File "/nfs/stak/users/kimh22/public_html/cs340_group39/NutriSphere_admin_panel/templates/index.html", line 16, in top-level template code
    <a href="{{ url_for('daily-trackers') }}">üóìÔ∏è Daily Trackers</a>
  File "/nfs/stak/users/kimh22/public_html/cs340_group39/NutriSphere_admin_panel/venv/lib64/python3.9/site-packages/flask/app.py", line 1121, in url_for
    return self.handle_url_build_error(error, endpoint, values)
  File "/nfs/stak/users/kimh22/public_html/cs340_group39/NutriSphere_admin_panel/venv/lib64/python3.9/site-packages/flask/app.py", line 1110, in url_for
    rv = url_adapter.build(  # type: ignore[union-attr]
  File "/nfs/stak/users/kimh22/public_html/cs340_group39/NutriSphere_admin_panel/venv/lib64/python3.9/site-packages/werkzeug/routing/map.py", line 924, in build
    raise BuildError(endpoint, values, method, self)
werkzeug.routing.exceptions.BuildError: Could not build url for endpoint 'daily-trackers'. Did you mean 'daily_trackers' instead?
[2025-02-25 01:43:05 -0800] [2638387] [CRITICAL] WORKER TIMEOUT (pid:2638397)
[2025-02-25 01:43:05 -0800] [2638397] [ERROR] Error handling request (no URI read)
Traceback (most recent call last):
  File "/nfs/stak/users/kimh22/public_html/cs340_group39/NutriSphere_admin_panel/venv/lib64/python3.9/site-packages/gunicorn/workers/sync.py", line 133, in handle
    req = next(parser)
  File "/nfs/stak/users/kimh22/public_html/cs340_group39/NutriSphere_admin_panel/venv/lib64/python3.9/site-packages/gunicorn/http/parser.py", line 41, in __next__
    self.mesg = self.mesg_class(self.cfg, self.unreader, self.source_addr, self.req_count)
  File "/nfs/stak/users/kimh22/public_html/cs340_group39/NutriSphere_admin_panel/venv/lib64/python3.9/site-packages/gunicorn/http/message.py", line 259, in __init__
    super().__init__(cfg, unreader, peer_addr)
  File "/nfs/stak/users/kimh22/public_html/cs340_group39/NutriSphere_admin_panel/venv/lib64/python3.9/site-packages/gunicorn/http/message.py", line 60, in __init__
    unused = self.parse(self.unreader)
  File "/nfs/stak/users/kimh22/public_html/cs340_group39/NutriSphere_admin_panel/venv/lib64/python3.9/site-packages/gunicorn/http/message.py", line 271, in parse
    self.get_data(unreader, buf, stop=True)
  File "/nfs/stak/users/kimh22/public_html/cs340_group39/NutriSphere_admin_panel/venv/lib64/python3.9/site-packages/gunicorn/http/message.py", line 262, in get_data
    data = unreader.read()
  File "/nfs/stak/users/kimh22/public_html/cs340_group39/NutriSphere_admin_panel/venv/lib64/python3.9/site-packages/gunicorn/http/unreader.py", line 36, in read
    d = self.chunk()
  File "/nfs/stak/users/kimh22/public_html/cs340_group39/NutriSphere_admin_panel/venv/lib64/python3.9/site-packages/gunicorn/http/unreader.py", line 63, in chunk
    return self.sock.recv(self.mxchunk)
  File "/nfs/stak/users/kimh22/public_html/cs340_group39/NutriSphere_admin_panel/venv/lib64/python3.9/site-packages/gunicorn/workers/base.py", line 204, in handle_abort
    sys.exit(1)
SystemExit: 1
[2025-02-25 01:43:05 -0800] [2638397] [INFO] Worker exiting (pid: 2638397)
[2025-02-25 01:43:05 -0800] [2638478] [INFO] Booting worker with pid: 2638478
[2025-02-25 01:44:39 -0800] [2638390] [INFO] Worker exiting (pid: 2638390)
[2025-02-25 01:44:39 -0800] [2638387] [INFO] Handling signal: term
[2025-02-25 01:44:39 -0800] [2638478] [INFO] Worker exiting (pid: 2638478)
[2025-02-25 01:44:39 -0800] [2638387] [INFO] Shutting down: Master
